Workbook

Sheet НДС по юрлицам
A1: Юридическое лицо / ИП | B1: Режим налогообложения | C1: Текущий статус НДС | D1: Ставка НДС | E1: Ставка НДС | F1: Ставка УСН/ Прибыль | G1: Доходы за 2025 год, руб. | H1: Порог освобождения, руб. | I1: Статус на 01.01.2026 | J1: Доходы за 2026 год по месяцам (ввод) | K1: Дата начала уплаты НДС по доходам 2026 | L1: Примечание
A2: Аргумент | B2: ОСНО | C2: Плательщик НДС | D2: 0.22 | E2: 22% | F2: 0.25
A3: ИП Рожков | B3: УСН «доходы» | C3: Плательщик НДС (с 2024 г., по данным компании) | D3: Указана действующая ставка НДС 5%. . | E3: 5% | F3: 1% | G3: 1.4640474e+08 | H3: 20000000 | I3: =IF(G3="","Заполнить доходы за 2025 год",IF(G3>20000000,"НДС с 01.01.2026",IF(J3>20000000,"НДС с месяца после превышения в 2026","Освобождение при доходе до 20 млн руб."))) | J3: ='Доходы 2026 по месяцам'!N2 | K3: Не применяется — уже плательщик НДС | L3: Ставка 5 % действует, пока доход с начала года ≤ 272,5 млн руб. При превышении — 7 % с 1-го числа следующего месяца. См. лист «Пороги и риски».
A4: Легкие деньки | B4: УСН «доходы минус раходы » | C4: Не плательщик НДС | D4: Порог 20 млн руб. применяется к организациям/ИП на УСН, имеющим право на освобождение. На ОСНО освобождение по этому порогу не применяется. | E4: Без НДС | F4: Уточнить | G4: 0 | H4: 20000000 | I4: =IF(G4="","Заполнить доходы за 2025 год",IF(G4>20000000,"НДС с 01.01.2026",IF(J4>20000000,"НДС с месяца после превышения в 2026","Освобождение при доходе до 20 млн руб."))) | J4: ='Доходы 2026 по месяцам'!N3 | K4: ='Доходы 2026 по месяцам'!P3
A5: Эль Карго | B5: УСН «доход» | C5: Не плательщик НДС | D5: Порог 20 млн руб. применяется к организациям/ИП на УСН, имеющим право на освобождение. На ОСНО освобождение по этому порогу не применяется. | E5: Без НДС | F5: Уточнить | G5: 887500 | H5: 20000000 | I5: =IF(G5="","Заполнить доходы за 2025 год",IF(G5>20000000,"НДС с 01.01.2026",IF(J5>20000000,"НДС с месяца после превышения в 2026","Освобождение при доходе до 20 млн руб."))) | J5: ='Доходы 2026 по месяцам'!N4 | K5: ='Доходы 2026 по месяцам'!P4
A6: Актив Про | B6: УСН «доходы минус раходы » | C6: Не плательщик НДС | D6: Порог 20 млн руб. применяется к организациям/ИП на УСН, имеющим право на освобождение. На ОСНО освобождение по этому порогу не применяется. | E6: Без НДС | F6: Уточнить | G6: 0 | H6: 20000000 | I6: =IF(G6="","Заполнить доходы за 2025 год",IF(G6>20000000,"НДС с 01.01.2026",IF(J6>20000000,"НДС с месяца после превышения в 2026","Освобождение при доходе до 20 млн руб."))) | J6: ='Доходы 2026 по месяцам'!N5 | K6: ='Доходы 2026 по месяцам'!P5

Sheet Пороги и риски
A1: Пороги НДС на УСН в 2026 году
A2: Освобождение от НДС, руб. | B2: 20000000
A3: Ставка 5 % — доход до, руб. | B3: 272500000
A4: Ставка 7 % — доход до (и лимит УСН), руб. | B4: 490500000
A5: Прошло месяцев 2026 (данные по) | B5: 9
A7: Юрлицо | B7: Ставка НДС сейчас | C7: Доход янв–сен 2026 | D7: Средний доход в месяц | E7: Прогноз на год (по среднему) | F7: Ближайший порог | G7: Запас до порога | H7: Сколько месяцев выдержит при среднем доходе | I7: Риск | J7: Доход за последний месяц (сентябрь)
A8: ИП Рожков | B8: 5% | C8: ='Доходы 2026 по месяцам'!N2 | D8: =C8/$B$5 | E8: =D8*12 | F8: =$B$3 | G8: =F8-C8 | H8: =IF(D8=0,"нет поступлений",G8/D8) | I8: =IF(G8<=0,"ПОРОГ ПРЕВЫШЕН",IF(OR(E8>F8,AND(J8>0,G8<J8)),"ВЫСОКИЙ: может превысить в ближайший месяц / до конца года",IF(E8>F8*0.8,"СРЕДНИЙ: прогноз больше 80 % порога","НИЗКИЙ"))) | J8: ='Доходы 2026 по месяцам'!J2
A9: Легкие деньки | B9: Без НДС | C9: ='Доходы 2026 по месяцам'!N3 | D9: =C9/$B$5 | E9: =D9*12 | F9: =$B$2 | G9: =F9-C9 | H9: =IF(D9=0,"нет поступлений",G9/D9) | I9: =IF(G9<=0,"ПОРОГ ПРЕВЫШЕН",IF(OR(E9>F9,AND(J9>0,G9<J9)),"ВЫСОКИЙ: может превысить в ближайший месяц / до конца года",IF(E9>F9*0.8,"СРЕДНИЙ: прогноз больше 80 % порога","НИЗКИЙ"))) | J9: ='Доходы 2026 по месяцам'!J3
A10: Актив Про | B10: Без НДС | C10: ='Доходы 2026 по месяцам'!N5 | D10: =C10/$B$5 | E10: =D10*12 | F10: =$B$2 | G10: =F10-C10 | H10: =IF(D10=0,"нет поступлений",G10/D10) | I10: =IF(G10<=0,"ПОРОГ ПРЕВЫШЕН",IF(OR(E10>F10,AND(J10>0,G10<J10)),"ВЫСОКИЙ: может превысить в ближайший месяц / до конца года",IF(E10>F10*0.8,"СРЕДНИЙ: прогноз больше 80 % порога","НИЗКИЙ"))) | J10: ='Доходы 2026 по месяцам'!J5
A11: Эль Карго | B11: Без НДС (нет данных) | C11: ='Доходы 2026 по месяцам'!N4 | D11: =C11/$B$5 | E11: =D11*12 | F11: =$B$2 | G11: =F11-C11 | H11: =IF(D11=0,"нет поступлений",G11/D11) | I11: =IF(G11<=0,"ПОРОГ ПРЕВЫШЕН",IF(OR(E11>F11,AND(J11>0,G11<J11)),"ВЫСОКИЙ: может превысить в ближайший месяц / до конца года",IF(E11>F11*0.8,"СРЕДНИЙ: прогноз больше 80 % порога","НИЗКИЙ"))) | J11: ='Доходы 2026 по месяцам'!J4
A13: Риски
A14: 1. ИП Рожков, переход на 7 %. Порог 5 % в 2026 году — 272,5 млн руб. дохода с начала года. На 30.09 доход ≈147,4 млн, в среднем ≈16,4 млн в месяц, прогноз на год ≈196,5 млн. Запас ≈125 млн: порог перейдут, только если в октябре–декабре будет больше 40 млн в месяц. Если перейдут, ставка 7 % действует с 1-го числа следующего месяца, её надо закладывать в калькуляторы закупок. Контролировать ежемесячно.
A15: 2. ИП Рожков, счёт 55.03. Через 55.03 проходит 115–285 млн в месяц (всего ≈1,5 млрд за 9 месяцев). Я считал это переводами между своими счетами (сколько пришло, столько и ушло). Если это выручка (эквайринг, маркетплейс, платёжный агент), доход превысит и порог 7 % (490,5 млн), и лимит УСН — будут ОСНО и НДС 22 %. Бухгалтеру надо подтвердить, что это за счёт.
A16: 3. ИП Рожков, «платим с 2024 года». Ставки 5 %/7 % на УСН появились только с 01.01.2025, до этого ИП на УСН не платил НДС (кроме как по счетам-фактурам с выделенным НДС и при импорте). Если в 2024 году НДС платили, значит был другой режим (ОСНО) — это стоит пояснить финдиректору. 5 % без вычетов выбирается на 12 кварталов подряд: с 2025 года отказаться от неё можно не раньше 2028 года.
A17: 4. ИП Рожков, вычетов нет. При 5 % входной НДС поставщиков не принимается к вычету, он входит в стоимость закупки. В калькуляторах закупок цена поставщика берётся вместе с НДС, а 5 % начисляется на цену продажи.
A18: 5. Легкие деньки, высокий риск. Только в сентябре поступило 13,5 млн, всего 14,6 млн, до 20 млн осталось ≈5,4 млн. Если это превысят в октябре, НДС будет с 01.11.2026: надо выбрать ставку (5 % без вычетов или 22 % с вычетами) и выставлять счета-фактуры. С 1-го числа следующего месяца цену в договорах и калькуляторах надо считать с НДС.
A19: 6. Актив Про: ≈8 млн за 9 месяцев, риск низкий, но через 55.03 проходят большие суммы (до 79 млн в месяц) — проверить, как в п. 2.
A20: 7. Эль Карго: нет выписки за 2026 год, риск оценить нельзя.
A21: 8. Порог 20 млн с 2027 года снижается до 15 млн, с 2028 — до 10 млн. Дальше пороги будут индексироваться: значения на следующий год нужно сверять с ФНС.

Sheet Чек-лист
A1: Чек-лист по задаче «Ставка НДС по юрлицам»
A3: № | B3: Что сделать | C3: Статус | D3: Кто | E3: Комментарий
A4: 1 | B4: Доходы 2026 по месяцам: Рожков, Легкие деньки, Актив Про | C4: Готово | E4: Лист «Доходы 2026 по месяцам», источник — анализ сч. 51 из 1С
A5: 2 | B5: Ставка НДС по 4 юрлицам | C5: Готово | E5: Аргумент 22 %, Рожков 5 %, Легкие деньки и Эль Карго — без НДС
A6: 3 | B6: Пороги 5 % / 7 % / 20 млн и риски | C6: Готово | E6: Лист «Пороги и риски»
A7: 4 | B7: Добавить 5-е юрлицо | C7: Не сделано | E7: В задании пять юрлиц, в таблице четыре
A8: 5 | B8: Выгрузить из 1С анализ сч. 51 по Эль Карго за 2026 | C8: Не сделано | E8: Без него риск по порогу 20 млн не оценить
A9: 6 | B9: Подтвердить у бухгалтера, что за счёт 55.03 у Рожкова и Актив Про | C9: Не сделано | D9: Бухгалтер | E9: Если это выручка — у Рожкова превышен лимит УСН, НДС 22 %
A10: 7 | B10: Пояснить режим Рожкова в 2024 году | C10: Не сделано | E10: Ставка 5 % на УСН действует только с 2025 г.
A11: 8 | B11: Легкие деньки: заранее выбрать ставку на случай превышения 20 млн (5 % или 22 %) | C11: Не сделано | D11: Финдиректор | E11: Запас 5,4 млн; при превышении в октябре — НДС с 01.11.2026
A12: 9 | B12: Поставить верную ставку в калькулятор по Чечне (КД-8) | C12: Не сделано | E12: Ставка того юрлица, через которое идёт закупка (у Рожкова 5 %, не 22 %)
A13: 10 | B13: Обновлять доходы каждый месяц | C13: Регулярно | E13: Особенно Легкие деньки (порог 20 млн) и Рожков (порог 7 % — 272,5 млн)

Sheet Доходы 2026 по месяцам
A1: Юридическое лицо / ИП | B1: Январь | C1: Февраль | D1: Март | E1: Апрель | F1: Май | G1: Июнь | H1: Июль | I1: Август | J1: Сентябрь | K1: Октябрь | L1: Ноябрь | M1: Декабрь | N1: Итого за 2026 | O1: Месяц превышения порога | P1: Начало уплаты НДС
A2: ИП Рожков | B2: 15566919 | C2: 17261837 | D2: 16150589 | E2: 18952428 | F2: 14611610 | G2: 13149234 | H2: 18308024 | I2: 17237918 | J2: 16171369 | N2: =SUM(B2:M2) | O2: =IF(($B2)>20000000,"Январь",IF(($B2+$C2)>20000000,"Февраль",IF(($B2+$C2+$D2)>20000000,"Март",IF(($B2+$C2+$D2+$E2)>20000000,"Апрель",IF(($B2+$C2+$D2+$E2+$F2)>20000000,"Май",IF(($B2+$C2+$D2+$E2+$F2+$G2)>20000000,"Июнь",IF(($B2+$C2+$D2+$E2+$F2+$G2+$H2)>20000000,"Июль",IF(($B2+$C2+$D2+$E2+$F2+$G2+$H2+$I2)>20000000,"Август",IF(($B2+$C2+$D2+$E2+$F2+$G2+$H2+$I2+$J2)>20000000,"Сентябрь",IF(($B2+$C2+$D2+$E2+$F2+$G2+$H2+$I2+$J2+$K2)>20000000,"Октябрь",IF(($B2+$C2+$D2+$E2+$F2+$G2+$H2+$I2+$J2+$K2+$L2)>20000000,"Ноябрь",IF(($B2+$C2+$D2+$E2+$F2+$G2+$H2+$I2+$J2+$K2+$L2+$M2)>20000000,"Декабрь","")))))))))))) | P2: =IF(O2="","Не превышен по введённым данным",DATE(2026,MATCH(O2,{"Январь","Февраль","Март","Апрель","Май","Июнь","Июль","Август","Сентябрь","Октябрь","Ноябрь","Декабрь"},0)+1,1))
A3: Легкие деньки | B3: 0 | C3: 0 | D3: 0 | E3: 0 | F3: 0 | G3: 0 | H3: 0 | I3: 1145535.8 | J3: 13496756 | N3: =SUM(B3:M3) | O3: =IF(($B3)>20000000,"Январь",IF(($B3+$C3)>20000000,"Февраль",IF(($B3+$C3+$D3)>20000000,"Март",IF(($B3+$C3+$D3+$E3)>20000000,"Апрель",IF(($B3+$C3+$D3+$E3+$F3)>20000000,"Май",IF(($B3+$C3+$D3+$E3+$F3+$G3)>20000000,"Июнь",IF(($B3+$C3+$D3+$E3+$F3+$G3+$H3)>20000000,"Июль",IF(($B3+$C3+$D3+$E3+$F3+$G3+$H3+$I3)>20000000,"Август",IF(($B3+$C3+$D3+$E3+$F3+$G3+$H3+$I3+$J3)>20000000,"Сентябрь",IF(($B3+$C3+$D3+$E3+$F3+$G3+$H3+$I3+$J3+$K3)>20000000,"Октябрь",IF(($B3+$C3+$D3+$E3+$F3+$G3+$H3+$I3+$J3+$K3+$L3)>20000000,"Ноябрь",IF(($B3+$C3+$D3+$E3+$F3+$G3+$H3+$I3+$J3+$K3+$L3+$M3)>20000000,"Декабрь","")))))))))))) | P3: =IF(O3="","Не превышен по введённым данным",DATE(2026,MATCH(O3,{"Январь","Февраль","Март","Апрель","Май","Июнь","Июль","Август","Сентябрь","Октябрь","Ноябрь","Декабрь"},0)+1,1))
A4: Эль Карго | N4: =SUM(B4:M4) | O4: =IF(($B4)>20000000,"Январь",IF(($B4+$C4)>20000000,"Февраль",IF(($B4+$C4+$D4)>20000000,"Март",IF(($B4+$C4+$D4+$E4)>20000000,"Апрель",IF(($B4+$C4+$D4+$E4+$F4)>20000000,"Май",IF(($B4+$C4+$D4+$E4+$F4+$G4)>20000000,"Июнь",IF(($B4+$C4+$D4+$E4+$F4+$G4+$H4)>20000000,"Июль",IF(($B4+$C4+$D4+$E4+$F4+$G4+$H4+$I4)>20000000,"Август",IF(($B4+$C4+$D4+$E4+$F4+$G4+$H4+$I4+$J4)>20000000,"Сентябрь",IF(($B4+$C4+$D4+$E4+$F4+$G4+$H4+$I4+$J4+$K4)>20000000,"Октябрь",IF(($B4+$C4+$D4+$E4+$F4+$G4+$H4+$I4+$J4+$K4+$L4)>20000000,"Ноябрь",IF(($B4+$C4+$D4+$E4+$F4+$G4+$H4+$I4+$J4+$K4+$L4+$M4)>20000000,"Декабрь","")))))))))))) | P4: =IF(O4="","Не превышен по введённым данным",DATE(2026,MATCH(O4,{"Январь","Февраль","Март","Апрель","Май","Июнь","Июль","Август","Сентябрь","Октябрь","Ноябрь","Декабрь"},0)+1,1))
A5: Актив Про | B5: 5000 | C5: 144260.62 | D5: 1073187.6 | E5: 1040425.2 | F5: 2041695.7 | G5: 1004152.4 | H5: 1020588.7 | I5: 1085442.7 | J5: 569933.37 | N5: =SUM(B5:M5) | O5: =IF(($B5)>20000000,"Январь",IF(($B5+$C5)>20000000,"Февраль",IF(($B5+$C5+$D5)>20000000,"Март",IF(($B5+$C5+$D5+$E5)>20000000,"Апрель",IF(($B5+$C5+$D5+$E5+$F5)>20000000,"Май",IF(($B5+$C5+$D5+$E5+$F5+$G5)>20000000,"Июнь",IF(($B5+$C5+$D5+$E5+$F5+$G5+$H5)>20000000,"Июль",IF(($B5+$C5+$D5+$E5+$F5+$G5+$H5+$I5)>20000000,"Август",IF(($B5+$C5+$D5+$E5+$F5+$G5+$H5+$I5+$J5)>20000000,"Сентябрь",IF(($B5+$C5+$D5+$E5+$F5+$G5+$H5+$I5+$J5+$K5)>20000000,"Октябрь",IF(($B5+$C5+$D5+$E5+$F5+$G5+$H5+$I5+$J5+$K5+$L5)>20000000,"Ноябрь",IF(($B5+$C5+$D5+$E5+$F5+$G5+$H5+$I5+$J5+$K5+$L5+$M5)>20000000,"Декабрь","")))))))))))) | P5: =IF(O5="","Не превышен по введённым данным",DATE(2026,MATCH(O5,{"Январь","Февраль","Март","Апрель","Май","Июнь","Июль","Август","Сентябрь","Октябрь","Ноябрь","Декабрь"},0)+1,1))
A7: Доход = поступления на р/с от покупателей (Дт 51 Кт 62, включая авансы 62.02) минус возвраты покупателям (Дт 62 Кт 51) + прочие доходы (Кт 91.01). Источник: анализ счёта 51 из 1С за январь–сентябрь 2026.
A8: Не включены: 55.03 (перевод между своими счетами), 57 (деньги в пути), 66 (займы), 60 (возвраты от поставщиков), 76 (прочие расчёты — проверить отдельно).
A9: Эль Карго: выписки по счёту 51 в файле нет — нужно выгрузить из 1С.

Sheet Пояснения
A1: Пояснение к таблице
A2: 1. В 2026 году основная ставка НДС составляет 22%.
A3: 2. Для организаций и ИП на УСН освобождение от НДС в 2026 году зависит от доходов за 2025 год: если доходы не превысили 20 млн руб., действует освобождение с 01.01.2026.
A4: 3. Если доходы за 2025 год превысили 20 млн руб., НДС начисляется с 01.01.2026. Если порог превышен в течение 2026 года, обязанность возникает с 1-го числа месяца, следующего за месяцем превышения.
A5: 4. Ставка 5% по НДС на УСН применяется без вычетов входного НДС; при общей ставке 22% вычеты возможны при соблюдении условий НК РФ.
A6: 5. Для «Легкие деньки», «Эль Карго» и «Актив Про» нужно уточнить налоговый режим и доходы за 2025 год. Если они применяют УСН и доходы не превысили порог, дата возникновения обязанности зависит от доходов 2026 года.
A7: 6. На листе «Доходы 2026 по месяцам» внесите доходы каждого месяца. Дата в таблице рассчитывается как первое число месяца, следующего за месяцем превышения 20 млн руб.
A8: 7. Для расчёта порога учитываются доходы для целей УСН, включая доходы от реализации и внереализационные доходы; не все денежные поступления автоматически являются доходом.
A9: 8. Для ИП Рожков и «Аргумент» дата уже зависит от указанного действующего статуса; формулы по доходам нужны прежде всего для трёх лиц, работающих без НДС.
A10: Источник: ФНС России, раздел «НДС при УСН» и материалы об изменениях налогов с 2026 года.

Sheet актив про 
A1: ООО "АКТИВПРО"
A2: Анализ счета 51 за 2026 г.
A4: Выводимые данные: БУ (данные бухгалтерского учета)
A6: Отбор: Банковские счета Равно "40702810212010782246, Филиал "Корпоративный" ПАО "Совкомбанк""
A8: Счет | B8: Кор. Счет | C8: Дебет | D8: Кредит
A9: Период
A10: 51 | B10: Начальное сальдо
A11: Обороты за Январь 26 | B11: Начальное сальдо
B12: 57 | C12: 3290
B13: 57.01 | C13: 3290
B14: 62 | C14: 5000
B15: 62.01 | C15: 5000
B16: 91 | D16: 6580
B17: 91.02 | D17: 6580
B18: Оборот | C18: 8290 | D18: 6580
B19: Конечное сальдо | C19: 1710
A20: Обороты за Февраль 26 | B20: Начальное сальдо | C20: 1710
B21: 57 | D21: 5000
B22: 57.01 | D22: 5000
B23: 62 | C23: 144260.62
B24: 62.01 | C24: 144260.62
B25: 68 | D25: 40091.86
B26: 68.90 | D26: 40091.86
B27: 91 | D27: 3390
B28: 91.02 | D28: 3390
B29: Оборот | C29: 144260.62 | D29: 48481.86
B30: Конечное сальдо | C30: 97488.76
A31: Обороты за Март 26 | B31: Начальное сальдо | C31: 97488.76
B32: 57 | D32: 250000
B33: 57.01 | D33: 250000
B34: 62 | C34: 1073187.6
B35: 62.01 | C35: 832777.65
B36: 62.02 | C36: 240410
B37: 68 | D37: 66131.84
B38: 68.90 | D38: 66131.84
B39: 69 | D39: 1134
B40: 69.11 | D40: 1134
B41: 91 | D41: 3290
B42: 91.02 | D42: 3290
B43: Оборот | C43: 1073187.6 | D43: 320555.84
...

Sheet лгкие деньки 
A1: ООО "ЛЕГКИЕ ДЕНЬКИ"
A2: Анализ счета 51 за 2026 г.
A4: Выводимые данные: БУ (данные бухгалтерского учета)
A6: Счет | B6: Кор. Счет | C6: Дебет | D6: Кредит
A7: Период
A8: 51 | B8: Начальное сальдо | C8: 1729864.2
A9: Обороты за Январь 26 | B9: Начальное сальдо | C9: 1729864.2
B10: 60 | D10: 581
B11: 60.01 | D11: 581
B12: 68 | D12: 200000
B13: 68.90 | D13: 200000
B14: 75 | D14: 1487700
B15: 75.02 | D15: 1487700
B16: 91 | D16: 15199
B17: 91.02 | D17: 15199
B18: Оборот | D18: 1703480
B19: Конечное сальдо | C19: 26384.24
A20: Обороты за Февраль 26 | B20: Начальное сальдо | C20: 26384.24
B21: 51 | C21: 490 | D21: 490
B22: 60 | D22: 2443
B23: 60.01 | D23: 1800
B24: 60.02 | D24: 643
B25: 91 | D25: 689
B26: 91.02 | D26: 689
B27: Оборот | C27: 490 | D27: 3622
B28: Конечное сальдо | C28: 23252.24
A29: Обороты за Апрель 26 | B29: Начальное сальдо | C29: 23252.24
B30: 51 | C30: 300 | D30: 300
B31: 66 | C31: 189000
B32: 66.03 | C32: 189000
B33: 68 | D33: 509
B34: 68.90 | D34: 509
B35: 70 | D35: 3410
B36: 76 | D36: 180540.66
B37: 76.09 | D37: 180540.66
B38: 91 | D38: 27298.24
B39: 91.02 | D39: 27298.24
B40: Оборот | C40: 189300 | D40: 212057.9
B41: Конечное сальдо | C41: 494.34
A42: Обороты за Май 26 | B42: Начальное сальдо | C42: 494.34
...

Sheet рожков 
A1: ИП Рожков Никита Олегович
A2: Анализ счета 51 за 9 месяцев 2026 г.
A4: Выводимые данные: БУ (данные бухгалтерского учета)
A6: Счет | B6: Кор. Счет | C6: Дебет | D6: Кредит
A7: Период
A8: 51 | B8: Начальное сальдо | C8: 678578.46
A9: Обороты за Январь 26 | B9: Начальное сальдо | C9: 678578.46
B10: 55 | C10: 2.079295e+08 | D10: 2.0781973e+08
B11: 55.03 | C11: 2.079295e+08 | D11: 2.0781973e+08
B12: 57 | C12: 7695140.5 | D12: 11645140
B13: 57.01 | C13: 7695140.5 | D13: 11645140
B14: 60 | C14: 2272278 | D14: 5535483.6
B15: 60.01 | D15: 833622.62
B16: 60.02 | C16: 2272278 | D16: 4701861
B17: 62 | C17: 15383459
B18: 62.01 | C18: 15160234
B19: 62.02 | C19: 223225.14
B20: 68 | D20: 2815277.1
B21: 68.90 | D21: 2815277.1
B22: 69 | D22: 28918.71
B23: 69.11 | D23: 28918.71
B24: 70 | D24: 447310.72
B25: 71 | D25: 93500
B26: 71.01 | D26: 93500
B27: 76 | D27: 3980231.8
B28: 76.02 | D28: 82000
B29: 76.10 | D29: 3898231.8
B30: 84 | D30: 975000
B31: 84.01 | D31: 975000
B32: 91 | C32: 183460.45 | D32: 46884.38
B33: 91.01 | C33: 183460.45
B34: 91.02 | D34: 46884.38
B35: Оборот | C35: 2.3346384e+08 | D35: 2.3338748e+08
B36: Конечное сальдо | C36: 754935.38
A37: Обороты за Февраль 26 | B37: Начальное сальдо | C37: 754935.38
B38: 55 | C38: 1.9138067e+08 | D38: 1.8959327e+08
B39: 55.03 | C39: 1.9138067e+08 | D39: 1.8959327e+08
B40: 57 | C40: 8295406.3 | D40: 13995406
B41: 57.01 | C41: 8295406.3 | D41: 13995406
B42: 60 | C42: 345416.98 | D42: 4206686.6
...
