Workbook

Sheet Vileda — инвентарь
A1: Vileda Professional — коды ТН ВЭД и расчёт таможенных платежей
A2: Источник: «Заявка на поставку клинингового инвентаря Vileda Professional». Страна происхождения — Китай (преференции ЕАЭС не применяются).
A3: Жёлтые ячейки — вводные (вес, цена, кол-во). Зелёным выделен код ТН ВЭД, розовым — низкая уверенность (нужна консультация брокера или предварительное решение ФТС). Ставки пошлин — по справочникам ЕТТ ЕАЭС, сверить на дату ввоза.
A5: № | B5: Наименование | C5: Категория / назначение | D5: Ед. изм. | E5: Кол-во | F5: Код ТН ВЭД ЕАЭС | G5: Описание по ТН ВЭД | H5: Пошлина, % | I5: Пошлина, €/кг (мин./специф.) | J5: Вес нетто ед., кг | K5: Цена за ед., USD | L5: Стоимость по инвойсу, USD | M5: Доставка до границы, USD | N5: Таможенная стоимость, ₽ | O5: Пошлина, ₽ | P5: НДС 22%, ₽ | Q5: Пошлина + НДС, ₽ | R5: Себестоимость ед. без НДС, ₽ | S5: Разрешительные документы | T5: Уверенность в коде | U5: Комментарий / альтернативы
A6: Тележки
A7: 1 | B7: Тележка клининговая Vileda UltraSpeed Pro | C7: Тележки | D7: шт | E7: 20 | F7: 8716800000 | G7: Транспортные средства без механических устройств для перемещения (ручные тележки) | H7: 0.125 | L7: =IF(AND(ISNUMBER(E7),ISNUMBER(K7)),E7*K7,0) | M7: =IF(SUM($L$6:$L$70)=0,0,L7/SUM($L$6:$L$70)*Параметры!$B$9) | N7: =(L7+M7)*Параметры!$B$4 | O7: =MAX(N7*N(H7),IF(AND(ISNUMBER(J7),ISNUMBER(E7)),E7*J7*N(I7)*Параметры!$B$5,0)) | P7: =(N7+O7)*Параметры!$B$6 | Q7: =O7+P7 | R7: =IF(OR(N(E7)=0,N7=0),"",(N7+O7+($D$78+$D$80+$D$81)*N7/$D$75)/E7) | S7: Не подпадает под техрегламенты ТР ТС/ЕАЭС — сертификат/декларация не нужны. По запросу брокера — отказное письмо органа по сертификации. | T7: средняя | U7: Тележка в сборе с вёдрами/прессом в одной поставке классифицируется как комплект по 8716.
A8: 2 | B8: Тележка клининговая Vileda UltraSpeed Mini | C8: Тележки (малые зоны) | D8: шт | E8: 20 | F8: 8716800000 | G8: Транспортные средства без механических устройств для перемещения (ручные тележки) | H8: 0.125 | L8: =IF(AND(ISNUMBER(E8),ISNUMBER(K8)),E8*K8,0) | M8: =IF(SUM($L$6:$L$70)=0,0,L8/SUM($L$6:$L$70)*Параметры!$B$9) | N8: =(L8+M8)*Параметры!$B$4 | O8: =MAX(N8*N(H8),IF(AND(ISNUMBER(J8),ISNUMBER(E8)),E8*J8*N(I8)*Параметры!$B$5,0)) | P8: =(N8+O8)*Параметры!$B$6 | Q8: =O8+P8 | R8: =IF(OR(N(E8)=0,N8=0),"",(N8+O8+($D$78+$D$80+$D$81)*N8/$D$75)/E8) | S8: Не подпадает под техрегламенты ТР ТС/ЕАЭС — сертификат/декларация не нужны. По запросу брокера — отказное письмо органа по сертификации. | T8: средняя
A9: 3 | B9: Тележка клининговая Vileda MicroBasic | C9: Тележки (базовая комплектация) | D9: шт | E9: 20 | F9: 8716800000 | G9: Транспортные средства без механических устройств для перемещения (ручные тележки) | H9: 0.125 | L9: =IF(AND(ISNUMBER(E9),ISNUMBER(K9)),E9*K9,0) | M9: =IF(SUM($L$6:$L$70)=0,0,L9/SUM($L$6:$L$70)*Параметры!$B$9) | N9: =(L9+M9)*Параметры!$B$4 | O9: =MAX(N9*N(H9),IF(AND(ISNUMBER(J9),ISNUMBER(E9)),E9*J9*N(I9)*Параметры!$B$5,0)) | P9: =(N9+O9)*Параметры!$B$6 | Q9: =O9+P9 | R9: =IF(OR(N(E9)=0,N9=0),"",(N9+O9+($D$78+$D$80+$D$81)*N9/$D$75)/E9) | S9: Не подпадает под техрегламенты ТР ТС/ЕАЭС — сертификат/декларация не нужны. По запросу брокера — отказное письмо органа по сертификации. | T9: средняя
A10: Вёдра и отжимные системы
A11: 4 | B11: Ведро с педальным отжимом Vileda EasyPress | C11: Отжимные системы | D11: шт | E11: 20 | F11: 3924900009 | G11: Хозяйственные изделия из пластмасс, прочие | H11: 0.065 | L11: =IF(AND(ISNUMBER(E11),ISNUMBER(K11)),E11*K11,0) | M11: =IF(SUM($L$6:$L$70)=0,0,L11/SUM($L$6:$L$70)*Параметры!$B$9) | N11: =(L11+M11)*Параметры!$B$4 | O11: =MAX(N11*N(H11),IF(AND(ISNUMBER(J11),ISNUMBER(E11)),E11*J11*N(I11)*Параметры!$B$5,0)) | P11: =(N11+O11)*Параметры!$B$6 | Q11: =O11+P11 | R11: =IF(OR(N(E11)=0,N11=0),"",(N11+O11+($D$78+$D$80+$D$81)*N11/$D$75)/E11) | S11: Не подпадает под техрегламенты ТР ТС/ЕАЭС — сертификат/декларация не нужны. По запросу брокера — отказное письмо органа по сертификации. | T11: высокая
A12: 5 | B12: Ведро двухсекционное Vileda Professional (грязная/чистая вода) | C12: Отжимные системы | D12: шт | E12: 20 | F12: 3924900009 | G12: Хозяйственные изделия из пластмасс, прочие | H12: 0.065 | L12: =IF(AND(ISNUMBER(E12),ISNUMBER(K12)),E12*K12,0) | M12: =IF(SUM($L$6:$L$70)=0,0,L12/SUM($L$6:$L$70)*Параметры!$B$9) | N12: =(L12+M12)*Параметры!$B$4 | O12: =MAX(N12*N(H12),IF(AND(ISNUMBER(J12),ISNUMBER(E12)),E12*J12*N(I12)*Параметры!$B$5,0)) | P12: =(N12+O12)*Параметры!$B$6 | Q12: =O12+P12 | R12: =IF(OR(N(E12)=0,N12=0),"",(N12+O12+($D$78+$D$80+$D$81)*N12/$D$75)/E12) | S12: Не подпадает под техрегламенты ТР ТС/ЕАЭС — сертификат/декларация не нужны. По запросу брокера — отказное письмо органа по сертификации. | T12: высокая
A13: 6 | B13: Ведро трёхсекционное с ситом-отжимом | C13: Отжимные системы | D13: шт | E13: 20 | F13: 3924900009 | G13: Хозяйственные изделия из пластмасс, прочие | H13: 0.065 | L13: =IF(AND(ISNUMBER(E13),ISNUMBER(K13)),E13*K13,0) | M13: =IF(SUM($L$6:$L$70)=0,0,L13/SUM($L$6:$L$70)*Параметры!$B$9) | N13: =(L13+M13)*Параметры!$B$4 | O13: =MAX(N13*N(H13),IF(AND(ISNUMBER(J13),ISNUMBER(E13)),E13*J13*N(I13)*Параметры!$B$5,0)) | P13: =(N13+O13)*Параметры!$B$6 | Q13: =O13+P13 | R13: =IF(OR(N(E13)=0,N13=0),"",(N13+O13+($D$78+$D$80+$D$81)*N13/$D$75)/E13) | S13: Не подпадает под техрегламенты ТР ТС/ЕАЭС — сертификат/декларация не нужны. По запросу брокера — отказное письмо органа по сертификации. | T13: высокая
A14: 7 | B14: Пресс отжимной навесной на ведро | C14: Отжимные системы | D14: шт | E14: 20 | F14: 3924900009 | G14: Хозяйственные изделия из пластмасс, прочие | H14: 0.065 | L14: =IF(AND(ISNUMBER(E14),ISNUMBER(K14)),E14*K14,0) | M14: =IF(SUM($L$6:$L$70)=0,0,L14/SUM($L$6:$L$70)*Параметры!$B$9) | N14: =(L14+M14)*Параметры!$B$4 | O14: =MAX(N14*N(H14),IF(AND(ISNUMBER(J14),ISNUMBER(E14)),E14*J14*N(I14)*Параметры!$B$5,0)) | P14: =(N14+O14)*Параметры!$B$6 | Q14: =O14+P14 | R14: =IF(OR(N(E14)=0,N14=0),"",(N14+O14+($D$78+$D$80+$D$81)*N14/$D$75)/E14) | S14: Не подпадает под техрегламенты ТР ТС/ЕАЭС — сертификат/декларация не нужны. По запросу брокера — отказное письмо органа по сертификации. | T14: средняя | U14: Если пресс металлический — 7323 99 000 0.
A15: Мопы влажной уборки
A16: 8 | B16: Моп Vileda UltraSpeed Twist Mop (сменный, петлевой) | C16: Мопы влажные — плоские/петлевые | D16: шт | E16: 100 | F16: 6307109000 | G16: Тряпки для мытья полов, протирочные материалы — прочие (тканые и др.) | H16: 0.13 | I16: 0.46 | L16: =IF(AND(ISNUMBER(E16),ISNUMBER(K16)),E16*K16,0) | M16: =IF(SUM($L$6:$L$70)=0,0,L16/SUM($L$6:$L$70)*Параметры!$B$9) | N16: =(L16+M16)*Параметры!$B$4 | O16: =MAX(N16*N(H16),IF(AND(ISNUMBER(J16),ISNUMBER(E16)),E16*J16*N(I16)*Параметры!$B$5,0)) | P16: =(N16+O16)*Параметры!$B$6 | Q16: =O16+P16 | R16: =IF(OR(N(E16)=0,N16=0),"",(N16+O16+($D$78+$D$80+$D$81)*N16/$D$75)/E16) | S16: Как правило, вне ТР ТС 017 (протирочные изделия хоз. назначения) — отказное письмо. Проверить обязательную маркировку «Честный знак» (лёгкая промышленность) для кода 6307 на дату ввоза. | T16: средняя | U16: Специфическая/комбинированная ставка — для расчёта обязательно укажите вес нетто. Если полотно трикотажное — 6307 10 100 0 (0,61 €/кг). Уточнить у поставщика тип полотна.
A17: 9 | B17: Моп плоский Vileda MicroTech (флет-моп, микрофибра) | C17: Мопы плоские | D17: шт | E17: 100 | F17: 6307101000 | G17: Тряпки для мытья полов, протирочные материалы — трикотажные | I17: 0.61 | L17: =IF(AND(ISNUMBER(E17),ISNUMBER(K17)),E17*K17,0) | M17: =IF(SUM($L$6:$L$70)=0,0,L17/SUM($L$6:$L$70)*Параметры!$B$9) | N17: =(L17+M17)*Параметры!$B$4 | O17: =MAX(N17*N(H17),IF(AND(ISNUMBER(J17),ISNUMBER(E17)),E17*J17*N(I17)*Параметры!$B$5,0)) | P17: =(N17+O17)*Параметры!$B$6 | Q17: =O17+P17 | R17: =IF(OR(N(E17)=0,N17=0),"",(N17+O17+($D$78+$D$80+$D$81)*N17/$D$75)/E17) | S17: Как правило, вне ТР ТС 017 (протирочные изделия хоз. назначения) — отказное письмо. Проверить обязательную маркировку «Честный знак» (лёгкая промышленность) для кода 6307 на дату ввоза. | T17: средняя | U17: Специфическая/комбинированная ставка — для расчёта обязательно укажите вес нетто. Если полотно тканое — 6307 10 900 0 (13%, не менее 0,46 €/кг).
A18: 10 | B18: Моп веревочный (шнуровой) из хлопка/вискозы | C18: Мопы для сильных загрязнений | D18: шт | E18: 50 | F18: 6307109000 | G18: Тряпки для мытья полов, протирочные материалы — прочие (тканые и др.) | H18: 0.13 | I18: 0.46 | L18: =IF(AND(ISNUMBER(E18),ISNUMBER(K18)),E18*K18,0) | M18: =IF(SUM($L$6:$L$70)=0,0,L18/SUM($L$6:$L$70)*Параметры!$B$9) | N18: =(L18+M18)*Параметры!$B$4 | O18: =MAX(N18*N(H18),IF(AND(ISNUMBER(J18),ISNUMBER(E18)),E18*J18*N(I18)*Параметры!$B$5,0)) | P18: =(N18+O18)*Параметры!$B$6 | Q18: =O18+P18 | R18: =IF(OR(N(E18)=0,N18=0),"",(N18+O18+($D$78+$D$80+$D$81)*N18/$D$75)/E18) | S18: Как правило, вне ТР ТС 017 (протирочные изделия хоз. назначения) — отказное письмо. Проверить обязательную маркировку «Честный знак» (лёгкая промышленность) для кода 6307 на дату ввоза. | T18: высокая | U18: Специфическая/комбинированная ставка — для расчёта обязательно укажите вес нетто.
A19: 11 | B19: Моп из микрофибры повышенной впитываемости (для больших разливов) | C19: Мопы влажные усиленные | D19: шт | E19: 50 | F19: 6307101000 | G19: Тряпки для мытья полов, протирочные материалы — трикотажные | I19: 0.61 | L19: =IF(AND(ISNUMBER(E19),ISNUMBER(K19)),E19*K19,0) | M19: =IF(SUM($L$6:$L$70)=0,0,L19/SUM($L$6:$L$70)*Параметры!$B$9) | N19: =(L19+M19)*Параметры!$B$4 | O19: =MAX(N19*N(H19),IF(AND(ISNUMBER(J19),ISNUMBER(E19)),E19*J19*N(I19)*Параметры!$B$5,0)) | P19: =(N19+O19)*Параметры!$B$6 | Q19: =O19+P19 | R19: =IF(OR(N(E19)=0,N19=0),"",(N19+O19+($D$78+$D$80+$D$81)*N19/$D$75)/E19) | S19: Как правило, вне ТР ТС 017 (протирочные изделия хоз. назначения) — отказное письмо. Проверить обязательную маркировку «Честный знак» (лёгкая промышленность) для кода 6307 на дату ввоза. | T19: средняя | U19: Специфическая/комбинированная ставка — для расчёта обязательно укажите вес нетто. Если полотно тканое — 6307 10 900 0.
A20: 12 | B20: Моп-твист (спин-моп) с ручным отжимом | C20: Мопы компактные / ручная уборка | D20: шт | E20: 50 | F20: 9603909100 | G20: Щётки и швабры для дома/хозяйственные, щётки для уборки покрытий | H20: 0.1 | L20: =IF(AND(ISNUMBER(E20),ISNUMBER(K20)),E20*K20,0) | M20: =IF(SUM($L$6:$L$70)=0,0,L20/SUM($L$6:$L$70)*Параметры!$B$9) | N20: =(L20+M20)*Параметры!$B$4 | O20: =MAX(N20*N(H20),IF(AND(ISNUMBER(J20),ISNUMBER(E20)),E20*J20*N(I20)*Параметры!$B$5,0)) | P20: =(N20+O20)*Параметры!$B$6 | Q20: =O20+P20 | R20: =IF(OR(N(E20)=0,N20=0),"",(N20+O20+($D$78+$D$80+$D$81)*N20/$D$75)/E20) | S20: Не подпадает под техрегламенты ТР ТС/ЕАЭС — сертификат/декларация не нужны. По запросу брокера — отказное письмо органа по сертификации. | T20: средняя | U20: Набор «швабра + ведро с центрифугой» классифицируется по швабре (9603).
A21: Мопы сухой уборки
A22: 13 | B22: Моп для сухой уборки (пыли) плоский, микрофибра | C22: Мопы сухие — сбор пыли | D22: шт | E22: 100 | F22: 6307101000 | G22: Тряпки для мытья полов, протирочные материалы — трикотажные | I22: 0.61 | L22: =IF(AND(ISNUMBER(E22),ISNUMBER(K22)),E22*K22,0) | M22: =IF(SUM($L$6:$L$70)=0,0,L22/SUM($L$6:$L$70)*Параметры!$B$9) | N22: =(L22+M22)*Параметры!$B$4 | O22: =MAX(N22*N(H22),IF(AND(ISNUMBER(J22),ISNUMBER(E22)),E22*J22*N(I22)*Параметры!$B$5,0)) | P22: =(N22+O22)*Параметры!$B$6 | Q22: =O22+P22 | R22: =IF(OR(N(E22)=0,N22=0),"",(N22+O22+($D$78+$D$80+$D$81)*N22/$D$75)/E22) | S22: Как правило, вне ТР ТС 017 (протирочные изделия хоз. назначения) — отказное письмо. Проверить обязательную маркировку «Честный знак» (лёгкая промышленность) для кода 6307 на дату ввоза. | T22: средняя | U22: Специфическая/комбинированная ставка — для расчёта обязательно укажите вес нетто. Если полотно тканое — 6307 10 900 0.
A23: 14 | B23: Моп для сухой уборки ворсистый (антистатический) | C23: Мопы сухие — антистатик | D23: шт | E23: 100 | F23: 6307101000 | G23: Тряпки для мытья полов, протирочные материалы — трикотажные | I23: 0.61 | L23: =IF(AND(ISNUMBER(E23),ISNUMBER(K23)),E23*K23,0) | M23: =IF(SUM($L$6:$L$70)=0,0,L23/SUM($L$6:$L$70)*Параметры!$B$9) | N23: =(L23+M23)*Параметры!$B$4 | O23: =MAX(N23*N(H23),IF(AND(ISNUMBER(J23),ISNUMBER(E23)),E23*J23*N(I23)*Параметры!$B$5,0)) | P23: =(N23+O23)*Параметры!$B$6 | Q23: =O23+P23 | R23: =IF(OR(N(E23)=0,N23=0),"",(N23+O23+($D$78+$D$80+$D$81)*N23/$D$75)/E23) | S23: Как правило, вне ТР ТС 017 (протирочные изделия хоз. назначения) — отказное письмо. Проверить обязательную маркировку «Честный знак» (лёгкая промышленность) для кода 6307 на дату ввоза. | T23: средняя | U23: Специфическая/комбинированная ставка — для расчёта обязательно укажите вес нетто. Если полотно тканое — 6307 10 900 0.
A24: 15 | B24: Моп-щётка для сбора крупного мусора | C24: Мопы сухие — крупный мусор | D24: шт | E24: 50 | F24: 9603909100 | G24: Щётки и швабры для дома/хозяйственные, щётки для уборки покрытий | H24: 0.1 | L24: =IF(AND(ISNUMBER(E24),ISNUMBER(K24)),E24*K24,0) | M24: =IF(SUM($L$6:$L$70)=0,0,L24/SUM($L$6:$L$70)*Параметры!$B$9) | N24: =(L24+M24)*Параметры!$B$4 | O24: =MAX(N24*N(H24),IF(AND(ISNUMBER(J24),ISNUMBER(E24)),E24*J24*N(I24)*Параметры!$B$5,0)) | P24: =(N24+O24)*Параметры!$B$6 | Q24: =O24+P24 | R24: =IF(OR(N(E24)=0,N24=0),"",(N24+O24+($D$78+$D$80+$D$81)*N24/$D$75)/E24) | S24: Не подпадает под техрегламенты ТР ТС/ЕАЭС — сертификат/декларация не нужны. По запросу брокера — отказное письмо органа по сертификации. | T24: высокая
A25: Держатели и рукоятки
A26: 16 | B26: Держатель для плоского мопа (флет-моп), быстросъёмный | C26: Держатели | D26: шт | E26: 25 | F26: 3926909709 | G26: Изделия из пластмасс прочие | H26: 0.065 | L26: =IF(AND(ISNUMBER(E26),ISNUMBER(K26)),E26*K26,0) | M26: =IF(SUM($L$6:$L$70)=0,0,L26/SUM($L$6:$L$70)*Параметры!$B$9) | N26: =(L26+M26)*Параметры!$B$4 | O26: =MAX(N26*N(H26),IF(AND(ISNUMBER(J26),ISNUMBER(E26)),E26*J26*N(I26)*Параметры!$B$5,0)) | P26: =(N26+O26)*Параметры!$B$6 | Q26: =O26+P26 | R26: =IF(OR(N(E26)=0,N26=0),"",(N26+O26+($D$78+$D$80+$D$81)*N26/$D$75)/E26) | S26: Не подпадает под техрегламенты ТР ТС/ЕАЭС — сертификат/декларация не нужны. По запросу брокера — отказное письмо органа по сертификации. | T26: средняя | U26: Если держатель алюминиевый — 7616 99 900 8 (9%).
A27: 17 | B27: Держатель для петлевого/веревочного мопа | C27: Держатели | D27: шт | E27: 25 | F27: 3926909709 | G27: Изделия из пластмасс прочие | H27: 0.065 | L27: =IF(AND(ISNUMBER(E27),ISNUMBER(K27)),E27*K27,0) | M27: =IF(SUM($L$6:$L$70)=0,0,L27/SUM($L$6:$L$70)*Параметры!$B$9) | N27: =(L27+M27)*Параметры!$B$4 | O27: =MAX(N27*N(H27),IF(AND(ISNUMBER(J27),ISNUMBER(E27)),E27*J27*N(I27)*Параметры!$B$5,0)) | P27: =(N27+O27)*Параметры!$B$6 | Q27: =O27+P27 | R27: =IF(OR(N(E27)=0,N27=0),"",(N27+O27+($D$78+$D$80+$D$81)*N27/$D$75)/E27) | S27: Не подпадает под техрегламенты ТР ТС/ЕАЭС — сертификат/декларация не нужны. По запросу брокера — отказное письмо органа по сертификации. | T27: средняя | U27: Если держатель металлический — 7616 / 7326.
A28: 18 | B28: Ручка телескопическая алюминиевая | C28: Рукоятки | D28: шт | E28: 50 | F28: 7616999008 | G28: Изделия из алюминия прочие | H28: 0.09 | L28: =IF(AND(ISNUMBER(E28),ISNUMBER(K28)),E28*K28,0) | M28: =IF(SUM($L$6:$L$70)=0,0,L28/SUM($L$6:$L$70)*Параметры!$B$9) | N28: =(L28+M28)*Параметры!$B$4 | O28: =MAX(N28*N(H28),IF(AND(ISNUMBER(J28),ISNUMBER(E28)),E28*J28*N(I28)*Параметры!$B$5,0)) | P28: =(N28+O28)*Параметры!$B$6 | Q28: =O28+P28 | R28: =IF(OR(N(E28)=0,N28=0),"",(N28+O28+($D$78+$D$80+$D$81)*N28/$D$75)/E28) | S28: Не подпадает под техрегламенты ТР ТС/ЕАЭС — сертификат/декларация не нужны. По запросу брокера — отказное письмо органа по сертификации. | T28: высокая | U28: Если из стекловолокна/карбона — классифицировать по материалу.
A29: 19 | B29: Ручка телескопическая для высоких потолков/стеллажей (удлинённая) | C29: Рукоятки | D29: шт | E29: 50 | F29: 7616999008 | G29: Изделия из алюминия прочие | H29: 0.09 | L29: =IF(AND(ISNUMBER(E29),ISNUMBER(K29)),E29*K29,0) | M29: =IF(SUM($L$6:$L$70)=0,0,L29/SUM($L$6:$L$70)*Параметры!$B$9) | N29: =(L29+M29)*Параметры!$B$4 | O29: =MAX(N29*N(H29),IF(AND(ISNUMBER(J29),ISNUMBER(E29)),E29*J29*N(I29)*Параметры!$B$5,0)) | P29: =(N29+O29)*Параметры!$B$6 | Q29: =O29+P29 | R29: =IF(OR(N(E29)=0,N29=0),"",(N29+O29+($D$78+$D$80+$D$81)*N29/$D$75)/E29) | S29: Не подпадает под техрегламенты ТР ТС/ЕАЭС — сертификат/декларация не нужны. По запросу брокера — отказное письмо органа по сертификации. | T29: высокая
A30: Сгоны и скребки для воды
A31: 20 | B31: Сгон для воды на пол (водосгон), резиновый, широкий | C31: Сгоны — полы | D31: шт | E31: 20 | F31: 9603909900 | G31: Прочие щётки, швабры (мопы); ракли резиновые (сгоны) | H31: 0.125 | L31: =IF(AND(ISNUMBER(E31),ISNUMBER(K31)),E31*K31,0) | M31: =IF(SUM($L$6:$L$70)=0,0,L31/SUM($L$6:$L$70)*Параметры!$B$9) | N31: =(L31+M31)*Параметры!$B$4 | O31: =MAX(N31*N(H31),IF(AND(ISNUMBER(J31),ISNUMBER(E31)),E31*J31*N(I31)*Параметры!$B$5,0)) | P31: =(N31+O31)*Параметры!$B$6 | Q31: =O31+P31 | R31: =IF(OR(N(E31)=0,N31=0),"",(N31+O31+($D$78+$D$80+$D$81)*N31/$D$75)/E31) | S31: Не подпадает под техрегламенты ТР ТС/ЕАЭС — сертификат/декларация не нужны. По запросу брокера — отказное письмо органа по сертификации. | T31: высокая | U31: Резиновые сгоны прямо названы в тексте позиции 9603.
A32: 21 | B32: Сгон для воды на пол, узкий (для труднодоступных зон/углов) | C32: Сгоны — полы | D32: шт | E32: 20 | F32: 9603909900 | G32: Прочие щётки, швабры (мопы); ракли резиновые (сгоны) | H32: 0.125 | L32: =IF(AND(ISNUMBER(E32),ISNUMBER(K32)),E32*K32,0) | M32: =IF(SUM($L$6:$L$70)=0,0,L32/SUM($L$6:$L$70)*Параметры!$B$9) | N32: =(L32+M32)*Параметры!$B$4 | O32: =MAX(N32*N(H32),IF(AND(ISNUMBER(J32),ISNUMBER(E32)),E32*J32*N(I32)*Параметры!$B$5,0)) | P32: =(N32+O32)*Параметры!$B$6 | Q32: =O32+P32 | R32: =IF(OR(N(E32)=0,N32=0),"",(N32+O32+($D$78+$D$80+$D$81)*N32/$D$75)/E32) | S32: Не подпадает под техрегламенты ТР ТС/ЕАЭС — сертификат/декларация не нужны. По запросу брокера — отказное письмо органа по сертификации. | T32: высокая
A33: 22 | B33: Сгон для стёкол (склиз) с мягкой резинкой | C33: Сгоны — стёкла | D33: шт | E33: 30 | F33: 9603909900 | G33: Прочие щётки, швабры (мопы); ракли резиновые (сгоны) | H33: 0.125 | L33: =IF(AND(ISNUMBER(E33),ISNUMBER(K33)),E33*K33,0) | M33: =IF(SUM($L$6:$L$70)=0,0,L33/SUM($L$6:$L$70)*Параметры!$B$9) | N33: =(L33+M33)*Параметры!$B$4 | O33: =MAX(N33*N(H33),IF(AND(ISNUMBER(J33),ISNUMBER(E33)),E33*J33*N(I33)*Параметры!$B$5,0)) | P33: =(N33+O33)*Параметры!$B$6 | Q33: =O33+P33 | R33: =IF(OR(N(E33)=0,N33=0),"",(N33+O33+($D$78+$D$80+$D$81)*N33/$D$75)/E33) | S33: Не подпадает под техрегламенты ТР ТС/ЕАЭС — сертификат/декларация не нужны. По запросу брокера — отказное письмо органа по сертификации. | T33: высокая
A34: 23 | B34: Сгон комбинированный (стекло + пол, двусторонний) | C34: Сгоны универсальные | D34: шт | E34: 20 | F34: 9603909900 | G34: Прочие щётки, швабры (мопы); ракли резиновые (сгоны) | H34: 0.125 | L34: =IF(AND(ISNUMBER(E34),ISNUMBER(K34)),E34*K34,0) | M34: =IF(SUM($L$6:$L$70)=0,0,L34/SUM($L$6:$L$70)*Параметры!$B$9) | N34: =(L34+M34)*Параметры!$B$4 | O34: =MAX(N34*N(H34),IF(AND(ISNUMBER(J34),ISNUMBER(E34)),E34*J34*N(I34)*Параметры!$B$5,0)) | P34: =(N34+O34)*Параметры!$B$6 | Q34: =O34+P34 | R34: =IF(OR(N(E34)=0,N34=0),"",(N34+O34+($D$78+$D$80+$D$81)*N34/$D$75)/E34) | S34: Не подпадает под техрегламенты ТР ТС/ЕАЭС — сертификат/декларация не нужны. По запросу брокера — отказное письмо органа по сертификации. | T34: высокая
A35: 24 | B35: Запасные резинки/лезвия для сгонов | C35: Сгоны — расходники | D35: уп | E35: 20 | F35: 4016999708 | G35: Изделия из вулканизованной резины прочие | H35: 0.1 | L35: =IF(AND(ISNUMBER(E35),ISNUMBER(K35)),E35*K35,0) | M35: =IF(SUM($L$6:$L$70)=0,0,L35/SUM($L$6:$L$70)*Параметры!$B$9) | N35: =(L35+M35)*Параметры!$B$4 | O35: =MAX(N35*N(H35),IF(AND(ISNUMBER(J35),ISNUMBER(E35)),E35*J35*N(I35)*Параметры!$B$5,0)) | P35: =(N35+O35)*Параметры!$B$6 | Q35: =O35+P35 | R35: =IF(OR(N(E35)=0,N35=0),"",(N35+O35+($D$78+$D$80+$D$81)*N35/$D$75)/E35) | S35: Не подпадает под техрегламенты ТР ТС/ЕАЭС — сертификат/декларация не нужны. По запросу брокера — отказное письмо органа по сертификации. | T35: средняя
A36: 25 | B36: Скребок для пола с металлическим лезвием (снятие наклеек/жвачки) | C36: Скребки | D36: шт | E36: 100 | F36: 8205598099 | G36: Инструменты ручные прочие | H36: 0.03 | L36: =IF(AND(ISNUMBER(E36),ISNUMBER(K36)),E36*K36,0) | M36: =IF(SUM($L$6:$L$70)=0,0,L36/SUM($L$6:$L$70)*Параметры!$B$9) | N36: =(L36+M36)*Параметры!$B$4 | O36: =MAX(N36*N(H36),IF(AND(ISNUMBER(J36),ISNUMBER(E36)),E36*J36*N(I36)*Параметры!$B$5,0)) | P36: =(N36+O36)*Параметры!$B$6 | Q36: =O36+P36 | R36: =IF(OR(N(E36)=0,N36=0),"",(N36+O36+($D$78+$D$80+$D$81)*N36/$D$75)/E36) | S36: Не подпадает под техрегламенты ТР ТС/ЕАЭС — сертификат/декларация не нужны. По запросу брокера — отказное письмо органа по сертификации. | T36: средняя | U36: Подсубпозиция 8205 59 80 делилась — 10-й знак сверить с брокером.
A37: Салфетки из микрофибры (цветовое кодирование)
A38: 26 | B38: Салфетки из микрофибры Vileda MicroFit — красный 40х40 | C38: Салфетки (цвет. код.) | D38: шт | E38: 200 | F38: 6307101000 | G38: Тряпки для мытья полов, протирочные материалы — трикотажные | I38: 0.61 | L38: =IF(AND(ISNUMBER(E38),ISNUMBER(K38)),E38*K38,0) | M38: =IF(SUM($L$6:$L$70)=0,0,L38/SUM($L$6:$L$70)*Параметры!$B$9) | N38: =(L38+M38)*Параметры!$B$4 | O38: =MAX(N38*N(H38),IF(AND(ISNUMBER(J38),ISNUMBER(E38)),E38*J38*N(I38)*Параметры!$B$5,0)) | P38: =(N38+O38)*Параметры!$B$6 | Q38: =O38+P38 | R38: =IF(OR(N(E38)=0,N38=0),"",(N38+O38+($D$78+$D$80+$D$81)*N38/$D$75)/E38) | S38: Как правило, вне ТР ТС 017 (протирочные изделия хоз. назначения) — отказное письмо. Проверить обязательную маркировку «Честный знак» (лёгкая промышленность) для кода 6307 на дату ввоза. | T38: высокая | U38: Специфическая/комбинированная ставка — для расчёта обязательно укажите вес нетто. Микрофибра MicroFit — трикотажное полотно (проверить по спецификации).
A39: 27 | B39: Салфетки из микрофибры Vileda MicroFit — синий 40х40 | C39: Салфетки (цвет. код.) | D39: шт | E39: 200 | F39: 6307101000 | G39: Тряпки для мытья полов, протирочные материалы — трикотажные | I39: 0.61 | L39: =IF(AND(ISNUMBER(E39),ISNUMBER(K39)),E39*K39,0) | M39: =IF(SUM($L$6:$L$70)=0,0,L39/SUM($L$6:$L$70)*Параметры!$B$9) | N39: =(L39+M39)*Параметры!$B$4 | O39: =MAX(N39*N(H39),IF(AND(ISNUMBER(J39),ISNUMBER(E39)),E39*J39*N(I39)*Параметры!$B$5,0)) | P39: =(N39+O39)*Параметры!$B$6 | Q39: =O39+P39 | R39: =IF(OR(N(E39)=0,N39=0),"",(N39+O39+($D$78+$D$80+$D$81)*N39/$D$75)/E39) | S39: Как правило, вне ТР ТС 017 (протирочные изделия хоз. назначения) — отказное письмо. Проверить обязательную маркировку «Честный знак» (лёгкая промышленность) для кода 6307 на дату ввоза. | T39: высокая | U39: Специфическая/комбинированная ставка — для расчёта обязательно укажите вес нетто.
A40: 28 | B40: Салфетки из микрофибры Vileda MicroFit — жёлтый 40х40 | C40: Салфетки (цвет. код.) | D40: шт | E40: 200 | F40: 6307101000 | G40: Тряпки для мытья полов, протирочные материалы — трикотажные | I40: 0.61 | L40: =IF(AND(ISNUMBER(E40),ISNUMBER(K40)),E40*K40,0) | M40: =IF(SUM($L$6:$L$70)=0,0,L40/SUM($L$6:$L$70)*Параметры!$B$9) | N40: =(L40+M40)*Параметры!$B$4 | O40: =MAX(N40*N(H40),IF(AND(ISNUMBER(J40),ISNUMBER(E40)),E40*J40*N(I40)*Параметры!$B$5,0)) | P40: =(N40+O40)*Параметры!$B$6 | Q40: =O40+P40 | R40: =IF(OR(N(E40)=0,N40=0),"",(N40+O40+($D$78+$D$80+$D$81)*N40/$D$75)/E40) | S40: Как правило, вне ТР ТС 017 (протирочные изделия хоз. назначения) — отказное письмо. Проверить обязательную маркировку «Честный знак» (лёгкая промышленность) для кода 6307 на дату ввоза. | T40: высокая | U40: Специфическая/комбинированная ставка — для расчёта обязательно укажите вес нетто.
A41: 29 | B41: Салфетки из микрофибры Vileda MicroFit — зелёный 40х40 | C41: Салфетки (цвет. код.) | D41: шт | E41: 200 | F41: 6307101000 | G41: Тряпки для мытья полов, протирочные материалы — трикотажные | I41: 0.61 | L41: =IF(AND(ISNUMBER(E41),ISNUMBER(K41)),E41*K41,0) | M41: =IF(SUM($L$6:$L$70)=0,0,L41/SUM($L$6:$L$70)*Параметры!$B$9) | N41: =(L41+M41)*Параметры!$B$4 | O41: =MAX(N41*N(H41),IF(AND(ISNUMBER(J41),ISNUMBER(E41)),E41*J41*N(I41)*Параметры!$B$5,0)) | P41: =(N41+O41)*Параметры!$B$6 | Q41: =O41+P41 | R41: =IF(OR(N(E41)=0,N41=0),"",(N41+O41+($D$78+$D$80+$D$81)*N41/$D$75)/E41) | S41: Как правило, вне ТР ТС 017 (протирочные изделия хоз. назначения) — отказное письмо. Проверить обязательную маркировку «Честный знак» (лёгкая промышленность) для кода 6307 на дату ввоза. | T41: высокая | U41: Специфическая/комбинированная ставка — для расчёта обязательно укажите вес нетто.
...

Sheet Оборудование (высота)
A1: Оборудование для клининга на высоте — коды ТН ВЭД и расчёт таможенных платежей
A2: Источник: «Оборудование для промышленного клининга на высоте — цех, 16 м». Страна происхождения — Китай.
A3: Жёлтые ячейки — вводные (вес, цена, кол-во). Зелёным выделен код ТН ВЭД, розовым — низкая уверенность (нужна консультация брокера или предварительное решение ФТС). Ставки пошлин — по справочникам ЕТТ ЕАЭС, сверить на дату ввоза.
A5: № | B5: Категория | C5: Оборудование | D5: Назначение / где применяется | E5: Кол-во (рекоменд.) | F5: Примечание | G5: Кол-во к расчёту | H5: Код ТН ВЭД ЕАЭС | I5: Описание по ТН ВЭД | J5: Пошлина, % | K5: Пошлина, €/кг (мин./специф.) | L5: Вес нетто ед., кг | M5: Цена за ед., USD | N5: Стоимость по инвойсу, USD | O5: Доставка до границы, USD | P5: Таможенная стоимость, ₽ | Q5: Пошлина, ₽ | R5: НДС 22%, ₽ | S5: Пошлина + НДС, ₽ | T5: Себестоимость ед. без НДС, ₽ | U5: Оценка стоимости документов, ₽ | V5: Разрешительные документы | W5: Уверенность в коде | X5: Комментарий / альтернативы
A6: Подъёмная техника
A7: 1 | B7: Подъёмная техника | C7: Шарнирная электровышка (Articulated Boom) | D7: Рабочая высота ~18–20 м; обход балок, кран-балок, трубопроводов | E7: 1–2 шт | F7: Genie Z-60/Z-62, JLG 600AJ, Haulotte HA20 RTJ (эл.) | G7: 1 | H7: 8427101000 | I7: Подъёмники/погрузчики самоходные с электродвигателем, высота подъёма ≥ 1 м | J7: 0 | N7: =IF(AND(ISNUMBER(G7),ISNUMBER(M7)),G7*M7,0) | O7: =IF(SUM($N$6:$N$23)=0,0,N7/SUM($N$6:$N$23)*Параметры!$B$10) | P7: =(N7+O7)*Параметры!$B$4 | Q7: =MAX(P7*N(J7),IF(AND(ISNUMBER(L7),ISNUMBER(G7)),G7*L7*N(K7)*Параметры!$B$5,0)) | R7: =(P7+Q7)*Параметры!$B$6 | S7: =Q7+R7 | T7: =IF(OR(N(G7)=0,P7=0),"",(P7+Q7+($D$31+$D$33+$D$34)*P7/$D$28)/G7) | U7: 80000 | V7: ТР ТС 010 — сертификат соответствия; ТР ТС 020 (ЭМС) — декларация. После ввоза: электронный паспорт самоходной машины (ЭПСМ) и регистрация в Гостехнадзоре; проверить утилизационный сбор (ПП РФ № 81); учёт в Ростехнадзоре при работе на опасном производственном объекте. Тяговые АКБ — опасный груз при перевозке. | W7: высокая | X7: Код — для электрической самоходной версии. Genie, JLG (США), Haulotte (Франция) — санкционные ограничения на поставки в РФ, риск для гарантии и запчастей. Из Китая надёжнее брать Dingli, Sinoboom, LGMG, XCMG, Zoomlion.
A8: 2 | B8: Подъёмная техника | C8: Телескопическая электровышка (Telescopic Boom) | D8: Большой горизонтальный вылет, работа через оборудование | E8: 1 шт (по потребности) | F8: Рабочая высота ~18–20 м | G8: 1 | H8: 8427101000 | I8: Подъёмники/погрузчики самоходные с электродвигателем, высота подъёма ≥ 1 м | J8: 0 | N8: =IF(AND(ISNUMBER(G8),ISNUMBER(M8)),G8*M8,0) | O8: =IF(SUM($N$6:$N$23)=0,0,N8/SUM($N$6:$N$23)*Параметры!$B$10) | P8: =(N8+O8)*Параметры!$B$4 | Q8: =MAX(P8*N(J8),IF(AND(ISNUMBER(L8),ISNUMBER(G8)),G8*L8*N(K8)*Параметры!$B$5,0)) | R8: =(P8+Q8)*Параметры!$B$6 | S8: =Q8+R8 | T8: =IF(OR(N(G8)=0,P8=0),"",(P8+Q8+($D$31+$D$33+$D$34)*P8/$D$28)/G8) | U8: 0 | V8: ТР ТС 010 — сертификат соответствия; ТР ТС 020 (ЭМС) — декларация. После ввоза: электронный паспорт самоходной машины (ЭПСМ) и регистрация в Гостехнадзоре; проверить утилизационный сбор (ПП РФ № 81); учёт в Ростехнадзоре при работе на опасном производственном объекте. Тяговые АКБ — опасный груз при перевозке. | W8: высокая | X8: Код — для электрической самоходной версии. Genie, JLG (США), Haulotte (Франция) — санкционные ограничения на поставки в РФ, риск для гарантии и запчастей. Из Китая надёжнее брать Dingli, Sinoboom, LGMG, XCMG, Zoomlion.
A9: 3 | B9: Подъёмная техника | C9: Паук-подъёмник (Spider Lift, гусеничный) | D9: Неровный пол, пороги, узкие проёмы от 70–80 см, без повреждения покрытия | E9: 1 шт (по потребности) | F9: Teupen Leo 23, Hinowa 21.75, Omme 2100RBDJ | G9: 1 | H9: 8427101000 | I9: Подъёмники/погрузчики самоходные с электродвигателем, высота подъёма ≥ 1 м | J9: 0 | N9: =IF(AND(ISNUMBER(G9),ISNUMBER(M9)),G9*M9,0) | O9: =IF(SUM($N$6:$N$23)=0,0,N9/SUM($N$6:$N$23)*Параметры!$B$10) | P9: =(N9+O9)*Параметры!$B$4 | Q9: =MAX(P9*N(J9),IF(AND(ISNUMBER(L9),ISNUMBER(G9)),G9*L9*N(K9)*Параметры!$B$5,0)) | R9: =(P9+Q9)*Параметры!$B$6 | S9: =Q9+R9 | T9: =IF(OR(N(G9)=0,P9=0),"",(P9+Q9+($D$31+$D$33+$D$34)*P9/$D$28)/G9) | U9: 80000 | V9: ТР ТС 010 — сертификат соответствия; ТР ТС 020 (ЭМС) — декларация. После ввоза: электронный паспорт самоходной машины (ЭПСМ) и регистрация в Гостехнадзоре; проверить утилизационный сбор (ПП РФ № 81); учёт в Ростехнадзоре при работе на опасном производственном объекте. Тяговые АКБ — опасный груз при перевозке. | W9: средняя | X9: Teupen, Hinowa, Omme часто дизель/гибрид: дизель → 8427 20 190 0 (ставку и утильсбор уточнить). Европейские бренды — санкционные ограничения.
A10: 4 | B10: Подъёмная техника | C10: Вышка-тура алюминиевая передвижная | D10: Точечные работы там, где подъёмник не пройдёт, высота 4–12 м | E10: 2–3 шт | F10: На колёсах, с фиксаторами | G10: 2 | H10: 7610909000 | I10: Металлоконструкции из алюминия, прочие | J10: 0.1 | N10: =IF(AND(ISNUMBER(G10),ISNUMBER(M10)),G10*M10,0) | O10: =IF(SUM($N$6:$N$23)=0,0,N10/SUM($N$6:$N$23)*Параметры!$B$10) | P10: =(N10+O10)*Параметры!$B$4 | Q10: =MAX(P10*N(J10),IF(AND(ISNUMBER(L10),ISNUMBER(G10)),G10*L10*N(K10)*Параметры!$B$5,0)) | R10: =(P10+Q10)*Параметры!$B$6 | S10: =Q10+R10 | T10: =IF(OR(N(G10)=0,P10=0),"",(P10+Q10+($D$31+$D$33+$D$34)*P10/$D$28)/G10) | U10: 15000 | V10: ТР ТС/ЕАЭС не распространяется. Рекомендуем добровольный сертификат ГОСТ Р и паспорт изделия — нужны для допуска к работам по Правилам по охране труда при работе на высоте. | W10: высокая
A11: 5 | B11: Подъёмная техника | C11: Стремянка-платформа | D11: Низкие зоны до 4–5 м | E11: 2 шт | G11: 2 | H11: 7616999008 | I11: Изделия из алюминия прочие | J11: 0.09 | N11: =IF(AND(ISNUMBER(G11),ISNUMBER(M11)),G11*M11,0) | O11: =IF(SUM($N$6:$N$23)=0,0,N11/SUM($N$6:$N$23)*Параметры!$B$10) | P11: =(N11+O11)*Параметры!$B$4 | Q11: =MAX(P11*N(J11),IF(AND(ISNUMBER(L11),ISNUMBER(G11)),G11*L11*N(K11)*Параметры!$B$5,0)) | R11: =(P11+Q11)*Параметры!$B$6 | S11: =Q11+R11 | T11: =IF(OR(N(G11)=0,P11=0),"",(P11+Q11+($D$31+$D$33+$D$34)*P11/$D$28)/G11) | U11: 10000 | V11: ТР ТС/ЕАЭС не распространяется. Рекомендуем добровольный сертификат ГОСТ Р и паспорт изделия — нужны для допуска к работам по Правилам по охране труда при работе на высоте. | W11: средняя | X11: Стальная — 7326 90 980 7.
A12: Клининговое оборудование
A13: 14 | B13: Клининговое оборудование | C13: Промышленный пылесос (класс L/M/H) | D13: Пыль, металлическая стружка, цемент — по типу производства | E13: 1–2 шт | F13: С длинной штангой/шлангом | G13: 1 | H13: 8508190009 | I13: Пылесосы со встроенным электродвигателем, прочие (> 2000 Вт или > 30 л) | J13: 0.03 | N13: =IF(AND(ISNUMBER(G13),ISNUMBER(M13)),G13*M13,0) | O13: =IF(SUM($N$6:$N$23)=0,0,N13/SUM($N$6:$N$23)*Параметры!$B$10) | P13: =(N13+O13)*Параметры!$B$4 | Q13: =MAX(P13*N(J13),IF(AND(ISNUMBER(L13),ISNUMBER(G13)),G13*L13*N(K13)*Параметры!$B$5,0)) | R13: =(P13+Q13)*Параметры!$B$6 | S13: =Q13+R13 | T13: =IF(OR(N(G13)=0,P13=0),"",(P13+Q13+($D$31+$D$33+$D$34)*P13/$D$28)/G13) | U13: 25000 | V13: ТР ТС 004 + ТР ТС 020 — декларация соответствия (для промышленных моделей обычно вместе с ТР ТС 010). Взрывозащищённое исполнение (ATEX / горючая пыль) — сертификат ТР ТС 012. | W13: высокая | X13: Код — для моделей > 2000 Вт или с баком > 30 л.
A14: 15 | B14: Клининговое оборудование | C14: Аппарат сухой чистки сжатым воздухом | D14: Обдув ферм, кабель-каналов, светильников | E14: 1 шт | G14: 1 | H14: 8424301000 | I14: Струйные очистные машины, работающие от сжатого воздуха | J14: 0 | N14: =IF(AND(ISNUMBER(G14),ISNUMBER(M14)),G14*M14,0) | O14: =IF(SUM($N$6:$N$23)=0,0,N14/SUM($N$6:$N$23)*Параметры!$B$10) | P14: =(N14+O14)*Параметры!$B$4 | Q14: =MAX(P14*N(J14),IF(AND(ISNUMBER(L14),ISNUMBER(G14)),G14*L14*N(K14)*Параметры!$B$5,0)) | R14: =(P14+Q14)*Параметры!$B$6 | S14: =Q14+R14 | T14: =IF(OR(N(G14)=0,P14=0),"",(P14+Q14+($D$31+$D$33+$D$34)*P14/$D$28)/G14) | U14: 25000 | V14: ТР ТС 010 + ТР ТС 004 + ТР ТС 020 — декларация соответствия. | W14: средняя | X14: Криобластинг (сухой лёд) — тот же код. Простой продувочный пистолет/компрессор — 8424 / 8414 80.
A15: 16 | B15: Клининговое оборудование | C15: Аппарат высокого/низкого давления с пеногенератором | D15: Обезжиривание металлоконструкций | E15: 1 шт | G15: 1 | H15: 8424300800 | I15: Аппараты водоструйные очистные со встроенным двигателем, без нагрева | J15: 0 | N15: =IF(AND(ISNUMBER(G15),ISNUMBER(M15)),G15*M15,0) | O15: =IF(SUM($N$6:$N$23)=0,0,N15/SUM($N$6:$N$23)*Параметры!$B$10) | P15: =(N15+O15)*Параметры!$B$4 | Q15: =MAX(P15*N(J15),IF(AND(ISNUMBER(L15),ISNUMBER(G15)),G15*L15*N(K15)*Параметры!$B$5,0)) | R15: =(P15+Q15)*Параметры!$B$6 | S15: =Q15+R15 | T15: =IF(OR(N(G15)=0,P15=0),"",(P15+Q15+($D$31+$D$33+$D$34)*P15/$D$28)/G15) | U15: 25000 | V15: ТР ТС 010 + ТР ТС 004 + ТР ТС 020 — декларация соответствия. | W15: средняя | X15: Ставка пошлины: НЕ ПОДТВЕРЖДЕНА — сверить. С нагревом воды — 8424 30 010 0 (0%). Ставку для 8424 30 080 0 сверить (у соседних подсубпозиций 0%).
A16: 17 | B16: Клининговое оборудование | C16: Насадки-щётки на удлинителях | D16: Очистка воздуховодов, кабель-каналов, кран-балок | E16: Комплект | G16: 1 | H16: 9603909100 | I16: Щётки и швабры для дома/хозяйственные, щётки для уборки покрытий | J16: 0.1 | N16: =IF(AND(ISNUMBER(G16),ISNUMBER(M16)),G16*M16,0) | O16: =IF(SUM($N$6:$N$23)=0,0,N16/SUM($N$6:$N$23)*Параметры!$B$10) | P16: =(N16+O16)*Параметры!$B$4 | Q16: =MAX(P16*N(J16),IF(AND(ISNUMBER(L16),ISNUMBER(G16)),G16*L16*N(K16)*Параметры!$B$5,0)) | R16: =(P16+Q16)*Параметры!$B$6 | S16: =Q16+R16 | T16: =IF(OR(N(G16)=0,P16=0),"",(P16+Q16+($D$31+$D$33+$D$34)*P16/$D$28)/G16) | U16: 0 | V16: Не подпадает под техрегламенты ТР ТС/ЕАЭС — сертификат/декларация не нужны. По запросу брокера — отказное письмо органа по сертификации. | W16: средняя | X16: Вращающиеся щётки для машины прочистки воздуховодов — 9603 50 000 0.
A17: 18 | B17: Клининговое оборудование | C17: Промышленный пылесос-влаговсос | D17: Уборка пола после мойки | E17: 1 шт | G17: 1 | H17: 8508190001 | I17: Пылесосы ≤ 2000 Вт с пылесборником ≤ 30 л | J17: 0.05 | N17: =IF(AND(ISNUMBER(G17),ISNUMBER(M17)),G17*M17,0) | O17: =IF(SUM($N$6:$N$23)=0,0,N17/SUM($N$6:$N$23)*Параметры!$B$10) | P17: =(N17+O17)*Параметры!$B$4 | Q17: =MAX(P17*N(J17),IF(AND(ISNUMBER(L17),ISNUMBER(G17)),G17*L17*N(K17)*Параметры!$B$5,0)) | R17: =(P17+Q17)*Параметры!$B$6 | S17: =Q17+R17 | T17: =IF(OR(N(G17)=0,P17=0),"",(P17+Q17+($D$31+$D$33+$D$34)*P17/$D$28)/G17) | U17: 25000 | V17: ТР ТС 004 + ТР ТС 020 — декларация соответствия (для промышленных моделей обычно вместе с ТР ТС 010). Взрывозащищённое исполнение (ATEX / горючая пыль) — сертификат ТР ТС 012. | W17: средняя | X17: ≤ 1500 Вт и ≤ 20 л — 8508 11 000 0 (5%); > 2000 Вт или > 30 л — 8508 19 000 9 (3%).
A18: 19 | B18: Клининговое оборудование | C18: Телескопическая штанга с водоподачей (Water-Fed Pole) | D18: Мытьё остеклённых зон/фонарей крыши | E18: 1–2 шт | F18: 6–20 м | G18: 1 | H18: 9603909100 | I18: Щётки и швабры для дома/хозяйственные, щётки для уборки покрытий | J18: 0.1 | N18: =IF(AND(ISNUMBER(G18),ISNUMBER(M18)),G18*M18,0) | O18: =IF(SUM($N$6:$N$23)=0,0,N18/SUM($N$6:$N$23)*Параметры!$B$10) | P18: =(N18+O18)*Параметры!$B$4 | Q18: =MAX(P18*N(J18),IF(AND(ISNUMBER(L18),ISNUMBER(G18)),G18*L18*N(K18)*Параметры!$B$5,0)) | R18: =(P18+Q18)*Параметры!$B$6 | S18: =Q18+R18 | T18: =IF(OR(N(G18)=0,P18=0),"",(P18+Q18+($D$31+$D$33+$D$34)*P18/$D$28)/G18) | U18: 0 | V18: Не подпадает под техрегламенты ТР ТС/ЕАЭС — сертификат/декларация не нужны. По запросу брокера — отказное письмо органа по сертификации. | W18: низкая | X18: Штанга без щётки — по материалу (алюминий 7616, карбон/стекловолокно — по материалу). Установка деминерализации воды — отдельно, 8421 21 000 9.
A19: 20 | B19: Клининговое оборудование | C19: Химия: обезжириватели, антикоррозийные составы | D19: По типу загрязнения (масло, копоть от сварки) | E19: По расходу | F19: Подбирается под материал поверхности | H19: 3402909000 | I19: Моющие и чистящие средства | J19: 0.065 | N19: =IF(AND(ISNUMBER(G19),ISNUMBER(M19)),G19*M19,0) | O19: =IF(SUM($N$6:$N$23)=0,0,N19/SUM($N$6:$N$23)*Параметры!$B$10) | P19: =(N19+O19)*Параметры!$B$4 | Q19: =MAX(P19*N(J19),IF(AND(ISNUMBER(L19),ISNUMBER(G19)),G19*L19*N(K19)*Параметры!$B$5,0)) | R19: =(P19+Q19)*Параметры!$B$6 | S19: =Q19+R19 | T19: =IF(OR(N(G19)=0,P19=0),"",(P19+Q19+($D$31+$D$33+$D$34)*P19/$D$28)/G19) | U19: 20000 | V19: Бытовая химия — свидетельство о госрегистрации (СГР). Промышленная — паспорт безопасности (ГОСТ 30333-2022), ТУ/СТО, добровольная декларация. Проверить состав на прекурсоры и сильнодействующие вещества; перевозка — как опасный груз (ADR/IMDG). Статус ТР ЕАЭС 041 «О безопасности химической продукции» уточнить на дату ввоза. | W19: средняя | X19: Антикоррозийные составы — 3403 99 / 3824 99 (отдельная строка в ДТ); растворители без ПАВ — 3814.
A20: Электрооборудование и питание
A21: 21 | B21: Электрооборудование и питание | C21: Удлинители промышленные на катушках | D21: Питание техники по цеху | E21: 3–5 шт | F21: IP44/IP54 | G21: 3 | H21: 8544429009 | I21: Проводники электрические ≤ 1000 В с соединительными приспособлениями, прочие | J21: 0.05 | N21: =IF(AND(ISNUMBER(G21),ISNUMBER(M21)),G21*M21,0) | O21: =IF(SUM($N$6:$N$23)=0,0,N21/SUM($N$6:$N$23)*Параметры!$B$10) | P21: =(N21+O21)*Параметры!$B$4 | Q21: =MAX(P21*N(J21),IF(AND(ISNUMBER(L21),ISNUMBER(G21)),G21*L21*N(K21)*Параметры!$B$5,0)) | R21: =(P21+Q21)*Параметры!$B$6 | S21: =Q21+R21 | T21: =IF(OR(N(G21)=0,P21=0),"",(P21+Q21+($D$31+$D$33+$D$34)*P21/$D$28)/G21) | U21: 30000 | V21: ТР ТС 004 — сертификат соответствия; ТР ТС 020 — при наличии электронных компонентов. | W21: высокая
A22: 22 | B22: Электрооборудование и питание | C22: Подключение к сети цеха / генератор | D22: Резерв при недостатке розеток | E22: 1 компл. | F22: Предпочтительно сеть цеха, не ДВС | H22: 8502112000 | I22: Электрогенераторные установки дизельные ≤ 7,5 кВА | N22: =IF(AND(ISNUMBER(G22),ISNUMBER(M22)),G22*M22,0) | O22: =IF(SUM($N$6:$N$23)=0,0,N22/SUM($N$6:$N$23)*Параметры!$B$10) | P22: =(N22+O22)*Параметры!$B$4 | Q22: =MAX(P22*N(J22),IF(AND(ISNUMBER(L22),ISNUMBER(G22)),G22*L22*N(K22)*Параметры!$B$5,0)) | R22: =(P22+Q22)*Параметры!$B$6 | S22: =Q22+R22 | T22: =IF(OR(N(G22)=0,P22=0),"",(P22+Q22+($D$31+$D$33+$D$34)*P22/$D$28)/G22) | U22: 25000 | V22: ТР ТС 010 + ТР ТС 004 + ТР ТС 020 — декларация соответствия. | W22: низкая | X22: Ставка пошлины: НЕ УСТАНОВЛЕНА — сверить. Нужна конкретика: бензиновый ≤ 7,5 кВА — 8502 20 200 0; аккумуляторная станция — 8507 60 / 8504 40. Ставку уточнить.
A23: 23 | B23: Электрооборудование и питание | C23: Аккумуляторные инструменты | D23: Там, где кабель мешает работе | E23: По потребности | F23: Мини-мойки, шуруповёрты | H23: 8467211000 | I23: Дрели и шуруповёрты аккумуляторные | J23: 0.085 | N23: =IF(AND(ISNUMBER(G23),ISNUMBER(M23)),G23*M23,0) | O23: =IF(SUM($N$6:$N$23)=0,0,N23/SUM($N$6:$N$23)*Параметры!$B$10) | P23: =(N23+O23)*Параметры!$B$4 | Q23: =MAX(P23*N(J23),IF(AND(ISNUMBER(L23),ISNUMBER(G23)),G23*L23*N(K23)*Параметры!$B$5,0)) | R23: =(P23+Q23)*Параметры!$B$6 | S23: =Q23+R23 | T23: =IF(OR(N(G23)=0,P23=0),"",(P23+Q23+($D$31+$D$33+$D$34)*P23/$D$28)/G23) | U23: 35000 | V23: ТР ТС 004 + ТР ТС 020 — сертификат соответствия (электроинструмент); ТР ЕАЭС 037 (RoHS) — декларация. | W23: высокая | X23: Аккумуляторные мини-мойки — 8424 30 080 0; прочий инструмент — по виду.
B26: ИТОГО ПО ПАРТИИ (одна декларация на товары)
B27: Стоимость по инвойсу, USD | D27: =SUM(N6:N23)
B28: Таможенная стоимость, ₽ | D28: =SUM(P6:P23)
B29: Ввозная пошлина, ₽ | D29: =SUM(Q6:Q23)
B30: НДС 22% при ввозе, ₽ | D30: =SUM(R6:R23)
B31: Таможенный сбор, ₽ | D31: =IF(D28=0,0,LOOKUP(D28,Параметры!$E$5:$E$12,Параметры!$G$5:$G$12))
B32: ИТОГО платежей на таможне, ₽ | D32: =D29+D30+D31
B33: Брокер (ДТ + доп. коды), ₽ | D33: =Параметры!$B$12+MAX(0,D36-Параметры!$B$14)*Параметры!$B$13
B34: Разрешительные документы (оценка), ₽ | D34: =SUM(U6:U23)
B35: ВСЕГО расходов на растаможку, ₽ | D35: =D32+D33+D34
B36: Разных кодов ТН ВЭД в партии | D36: 12
B37: в т. ч. НДС к вычету (при ОСНО), ₽ | D37: =D30
B38: Себестоимость партии на складе без НДС (без доставки по РФ), ₽ | D38: =D28+D29+D31+D33+D34

Sheet Параметры
A1: Параметры расчёта (РФ, 2026)
A2: Жёлтые ячейки с синим шрифтом — вводные, меняйте их. Остальное считается формулами.
E3: Таможенный сбор за выпуск (ПП РФ № 1637, ред. с 01.01.2026)
A4: Курс USD, ₽ (ЦБ РФ на дату регистрации ДТ) | B4: 82 | C4: Заглушка — подставьте курс ЦБ на дату подачи декларации. | E4: ТС от, ₽ | F4: ТС до, ₽ | G4: Сбор, ₽
A5: Курс EUR, ₽ (для специфических пошлин в €/кг) | B5: 95 | C5: Заглушка — подставьте курс ЦБ. | E5: 0 | F5: 200000 | G5: 1231
A6: Ставка НДС при ввозе | B6: 0.22 | C6: Ст. 164 НК РФ в ред. 425-ФЗ: 22% с 01.01.2026. База = таможенная стоимость + пошлина (+ акциз). | E6: 200000.01 | F6: 450000 | G6: 2462
A7: Валюта цен поставщика | B7: USD | C7: Цены в листах вводятся в этой валюте (для CNY поменяйте курс в B4 на курс юаня). | E7: 450000.01 | F7: 1200000 | G7: 4924
E8: 1200000 | F8: 2700000 | G8: 13541
A9: Доставка + страховка до границы ЕАЭС — партия Vileda, USD | B9: 0 | C9: Входит в таможенную стоимость; распределяется по позициям пропорционально стоимости. | E9: 2700000 | F9: 4200000 | G9: 18465
A10: Доставка + страховка до границы ЕАЭС — партия Оборудование, USD | B10: 0 | C10: То же. | E10: 4200000 | F10: 5500000 | G10: 24620
E11: 5500000 | F11: 10000000 | G11: 49240
A12: Брокер: оформление одной ДТ, ₽ | B12: 25000 | C12: Рыночная оценка 15–35 тыс. ₽ (Москва/СПб, 2026). Уточните у своего брокера. | E12: 10000000 | F12: и выше | G12: 73860
A13: Брокер: доплата за каждый код сверх включённых, ₽ | B13: 1000 | C13: Типично 500–1500 ₽ за доп. код.
A14: Кодов ТН ВЭД, включённых в базовую цену ДТ | B14: 5 | E14: Сбор взимается за каждую декларацию (ДТ) по суммарной таможенной стоимости товаров в ней.
A15: Документы по партии Vileda (отказные письма и т. п.), ₽ | B15: 10000 | C15: Оценка: отказное письмо 2–5 тыс. ₽ на группу товаров.
A18: Формулы, по которым считаются листы
A19: • Таможенная стоимость (ТС) = (цена × кол-во + доля доставки до границы) × курс
A20: • Пошлина = MAX(ТС × ставка %, вес нетто × ставка €/кг × курс EUR) — для комбинированных ставок «X%, но не менее Y €/кг»
A21: • НДС = (ТС + пошлина) × 22%. Таможенный сбор в базу НДС не входит
A22: • На ОСНО ввозной НДС принимается к вычету; на УСН — включается в себестоимость
A23: • Себестоимость ед. без НДС = (ТС + пошлина + доля сбора, брокера и документов) / кол-во

Sheet Документы и риски
A1: Сертификаты, лицензии и риски при ввозе из Китая
A3: Лицензии | B3: Лицензии Минпромторга на эти товары НЕ нужны: они не входят в перечни ограниченных к ввозу (Решение Коллегии ЕЭК № 30), товаров двойного назначения нет. Разрешительные документы — только техрегламенты ЕАЭС (см. колонку «Разрешительные документы»).
A4: Сертификаты — итог | B4: Vileda (инвентарь): сертификация не требуется, достаточно отказных писем; исключение — Windomatic (электроприбор, ТР ТС 004/020/037). Оборудование: подъёмники — сертификат ТР ТС 010; пылесосы, мойки, аппараты — декларации ТР ТС 004/020/010; удлинители и электроинструмент — сертификаты ТР ТС 004; химия — СГР или паспорт безопасности. Документы оформляются на заявителя-резидента ЕАЭС (ваше юрлицо или аккредитованного представителя) до подачи ДТ.
A5: Товарный знак Vileda | B5: Vileda — товарный знак Freudenberg. Проверьте его в Таможенном реестре объектов интеллектуальной собственности (ТРОИС ФТС). При закупке «Vileda» у китайских продавцов высок риск контрафакта: таможня может приостановить выпуск на 10 раб. дней, правообладатель может потребовать уничтожения. Нужны документы о происхождении у официального дистрибьютора, либо закупайте аналоги без бренда.
A6: Санкции | B6: Genie, JLG (США), Haulotte (Франция), Teupen (Германия), Hinowa (Италия) — поставки в РФ ограничены санкциями. Серый ввоз через Китай — риск по гарантии, запчастям и блокировке платежей. Китайские аналоги: Dingli, Sinoboom, LGMG, XCMG, Zoomlion (есть сервис в РФ).
A7: Самоходная техника | B7: Самоходные подъёмники: ЭПСМ, регистрация в Гостехнадзоре, проверка утилизационного сбора (ПП РФ № 81; суммы существенные — уточнить до контракта). Если сбор применяется — он платится до выпуска и может сильно превысить пошлину (0%).
A8: Преференции | B8: Китай исключён из системы тарифных преференций ЕАЭС (с 12.10.2021) — применяются полные ставки ЕТТ, сертификат происхождения формы A не снижает пошлину.
A9: НДС | B9: 22% с 01.01.2026 (425-ФЗ). На ОСНО — к вычету после выпуска; на УСН ввозной НДС платится, но идёт в себестоимость.
A10: Таможенная стоимость | B10: Риск корректировки таможенной стоимости (КТС), если цена ниже профиля риска ФТС. Нужны контракт, инвойс, упаковочный лист, транспортные документы, платёжки, прайс-лист/коммерческое предложение производителя, спецификации с весом нетто по каждой позиции.
A11: Валютный контроль | B11: Импортный контракт на сумму ≥ 3 млн ₽ ставится на учёт в уполномоченном банке (Инструкция ЦБ № 181-И).
A12: Спорные коды | B12: Низкая уверенность: магнитная щётка-подметалка, штанга с водоподачей, генератор. Для них можно запросить предварительное решение ФТС о классификации (бесплатно, срок до 90 дней) или согласовать код с брокером до отгрузки.
A13: Специфические пошлины | B13: На микрофибру (6307 10 100 0) пошлина — 0,61 €/кг, на прочие и нетканые тряпки — 13%, но не менее 0,46 €/кг. Для расчёта обязательно запросите у поставщика вес нетто по каждой позиции.
A14: Опасные грузы | B14: Химия (обезжириватели), Li-ion аккумуляторы (инструмент, Windomatic, тяговые АКБ подъёмников) — перевозка как опасный груз: нужен MSDS, влияет на стоимость фрахта.

Sheet Источники
A1: Источники и оговорки
A3: 1. Коды подобраны по текстам позиций ТН ВЭД ЕАЭС и Пояснениям к ТН ВЭД по описанию товаров из заявок, без спецификаций и фото. Окончательный код в ДТ определяет декларант (брокер).
A4: 2. Ставки пошлин — ЕТТ ЕАЭС (Решение Совета ЕЭК № 80 от 14.09.2021 в действ. ред.) по данным открытых справочников (Альта-Софт, IFCG, TKS, kodtnved.ru), сверены через поиск в сентябре 2026. Прямой доступ к базам из среды расчёта был закрыт — перед подачей ДТ сверьте каждую ставку.
A5: 3. НДС 22% — Федеральный закон № 425-ФЗ (с 01.01.2026).
A6: 4. Таможенные сборы — ПП РФ от 28.11.2024 № 1637 (ставки с 01.01.2026).
A7: 5. Техрегламенты: ТР ТС 004/2011 (низковольтное оборудование), 010/2011 (машины и оборудование), 012/2011 (взрывозащита), 017/2011 (лёгкая промышленность), 020/2011 (ЭМС), ТР ЕАЭС 037/2016 (RoHS), ТР ЕАЭС 041/2017 (химическая продукция).
A8: 6. Стоимость брокера и сертификации — рыночные оценки, не прайс конкретного исполнителя.
A9: 7. Курсы валют в «Параметрах» — заглушки, подставьте курс ЦБ РФ.

Sheet Чек-лист до заказа
A1: Что сделать до заказа (прямой импорт Китай → РФ, 2026)
A2: Отмечайте выполнение в колонке «Статус». Порядок шагов — рекомендуемый.
A4: Этап | B4: Что сделать | C4: Статус
A5: 1. Схема | B5: Выбрать схему: (а) свой контракт + свой валютный счёт + брокер — дешевле, всё под контролем; (б) ВЭД-агент «под ключ» — вы платите рублями агенту, он сам контрактует и оплачивает Китай (+3–7% к стоимости, быстрее старт); (в) купить у российского импортёра. Для регулярных закупок — схема (а).
A6: 1. Схема | B6: Не брать товар, растаможенный в Казахстане/Киргизии/Армении: с 01.06.2026 такой ввоз идёт через СПОТ (уведомление ФНС, QR-код, обеспечительный платёж НДС до ввоза). Прямой ввоз из Китая с растаможкой в РФ и транзит через Казахстан под таможенным транзитом под СПОТ не подпадают.
A7: 2. Поставщик | B7: Проверить поставщика: бизнес-лицензия (qcc.com / gsxt.gov.cn), завод или трейдер, опыт работы с РФ, готовность отгружать в РФ. По Vileda — подтверждение легальности товарного знака; по Genie/JLG/Haulotte — санкционный риск, рассмотреть Dingli/Sinoboom/LGMG/XCMG.
A8: 2. Поставщик | B8: Получить спецификации по каждой позиции: состав/материал, вес нетто и брутто, габариты, фото, паспорта, мощность/напряжение, тип АКБ, MSDS на химию и аккумуляторы. Без веса нетто не посчитать пошлину на микрофибру.
A9: 2. Поставщик | B9: Заранее спросить: в каком банке счёт поставщика и принимает ли он платежи из РФ в юанях (CNY). Крупные госбанки КНР часто отклоняют; региональные банки и счета в спецрайонах — лучше.
A10: 3. Брокер | B10: Выбрать таможенного представителя из реестра ФТС, согласовать коды ТН ВЭД и ставки по этой таблице ДО отгрузки, стоимость (ДТ + доп. коды), пункт оформления (ближе к вашему складу).
A11: 3. Брокер | B11: Спорные коды — предварительное решение ФТС (до 90 дней) или письменное подтверждение брокера.
A12: 4. Документы | B12: Оформить сертификаты/декларации ЕАЭС ДО прибытия товара (заявитель — ваше юрлицо). Для ТР ТС 004/020 нужны протоколы испытаний — возможно, образцы. Отказные письма на инвентарь Vileda. Проверить «Честный знак» для кода 6307.
A13: 4. Документы | B13: Маркировка на упаковке: знак EAC (для сертифицированных), информация на русском языке (наименование, изготовитель, импортёр) — передать макет поставщику до производства.
A14: 5. Контракт | B14: Внешнеторговый контракт в юанях (CNY) — расчёты в USD/EUR с Китаем практически не проходят. Двуязычный (RU/EN или RU/CN).
A15: 5. Контракт | B15: В контракте: спецификации-приложения (наименование, кол-во, цена, вес), Инкотермс 2020 (FOB порт / EXW / DAP граница), условия оплаты (напр. 30% аванс / 70% после отгрузки по копии коносамента/CMR), срок поставки, требования к упаковке и маркировке, рекламации, форс-мажор включая санкции и отказ банков, арбитраж (МКАС ТПП РФ или CIETAC).
A16: 5. Контракт | B16: Оговорка о возможности оплаты третьим лицом (платёжным агентом) — на случай, если прямой платёж не пройдёт. Без неё оплата через агента — нарушение валютного законодательства.
... A22: 9. После ввоза | B22: Подъёмники: ЭПСМ, регистрация в Гостехнадзоре, утильсбор. Бухучёт импорта, вычет НДС по ДТ и платёжке.
